Workbook

Sheet Read me
A1: India agency account map and poaching target list
A2: Prepared for Mask360 new business. Research as of 29 Sep 2026.
A4: What is inside
A5: Target list | B5: One row per brand (908 brands), ranked by a 10 point priority score. Shows who holds the account today, what just changed and why now. 63 brands score A (9 or 10) and 177 score B (7 or 8). Yellow columns are yours to fill in.
A6: In play now | B6: Pitches, reviews, new marketing leaders and account moves from 2026, newest first. Start here for timing.
A7: Agency roster | B7: The answer to 'which agency has what': 187 agencies with their luxury and premium accounts listed first. (L) marks a luxury brand.
A8: Agency turmoil 2025-26 | B8: Mergers, sales, exits and probes that make an agency's clients poachable, each with a source and the accounts exposed.
A9: Category by group | B9: How many current relationships each holding company has in each category. The Unknown or in-house column counts brands with no credited agency.
A10: All relationships | B10: The full evidence base: 1226 brand to agency relationships, each with evidence, date, confidence and a source link. Filter by any column.
A12: How the priority score works
A13: Score = Fit + Tier + Timing | B13: Out of 10. A = 9 or 10, B = 7 or 8, C = 6 or less. The score and priority are live formulas: change Timing pts and they update (sort by Score to re-rank).
A14: Fit pts (0 to 4) | B14: How close the category is to Mask360's luxury and premium lanes: Luxury hospitality & travel 4; Jewellery & watches 4; Fashion & luxury retail 4; Real estate 4; Beauty & personal care 3; Alcobev 3; Automotive 3; Wellness, fitness & sport 3; BFSI & wealth 2; Premium F&B & QSR 2; Aviation 2; Consumer tech & D2C 1; E-commerce & quick commerce 1; FMCG 1; Telecom & media 1; Healthcare 1; Other 1; Education 0.
A15: Tier pts (0 to 3) | B15: Luxury 3, Premium 2, Mass 0. Tier is the research agents' judgement of the brand's positioning.
A16: Timing pts (0 to 3) | B16: Pitch or review live = 3. Strong triggers add 2 each: leadership change (at the brand or the incumbent agency), incumbent agency in turmoil (merger, sale, probe), open mandates (channels with no agency). Weak triggers add 1: no agency credited at all, split roster, long tenure, launch or fresh funding, renewal due. Capped at 3. 0 = no trigger found, or the brand moved agency since Mar 2026 and nothing is left open (honeymoon). Blue cells: overwrite them when you know better.
A17: Why now (triggers) | B17: Keyword flags read from the poaching signals. Treat them as a prompt to read the signal text, not as a verdict.
A18: Mask360 relationship | B18: Brands matching Mask360's current client names (per its skill files) are marked Client and ranked last. L'Oreal group brands are marked as an expansion opportunity rather than a poach. Correct this column if the client list has changed.
A20: Status and confidence
A21: Status | B21: Active = relationship confirmed and current. Won recently = new appointment in the last months. In review = pitch or review reported. Recently lost = the brand moved away (the new agency usually has its own row). Unclear = older or indirect evidence, relationship may have lapsed.
A22: Confidence | B22: High = trade press or agency site dated 2024 to 2026 stating the relationship. Medium = older, a campaign credit only, or a news feed link. Low = client logo, inference, or no agency found.
A23: Unknown or in-house | B23: Where research found no agency, the brand is still listed. These are often the easiest doors: the work is in-house or with small shops.
A25: How to use it
A26: 1. Filter | B26: Target list: filter Priority = A, then your categories. Read Current agency, Why now and Poaching signals.
A27: 2. Check | B27: Open Source 1 before any outreach. Verify anything marked Low confidence or 'unverified'.
A28: 3. Track | B28: Fill the yellow columns: Owner, Outreach status (dropdown), Next step, Notes. Example: Owner 'Kaavish', status 'Contacted', next step 'Intro via ex-colleague of new CMO'.
A29: 4. Refresh | B29: Agency rosters move monthly. Re-check the In play now sheet before each outreach sprint.
A31: Method and limits
A32: Sources | B32: Eleven parallel research streams covered WPP, Publicis, Omnicom (two streams), Dentsu, Havas, Cheil and Hakuhodo, independent creative agencies, independent digital and social agencies, luxury boutiques with PR and events, live pitches and leadership moves, and two brand-first sweeps of premium categories. Main sources were afaqs, Storyboard18, MediaNews4U, Social Samosa, Campaign Brief Asia, Adgully, Manifest, IMPACT, agency websites and award credits.
A33: Gaps | B33: The shared web search allowance ran out early, so most research came from reading trade press pages and news feeds directly. exchange4media, bestmediainfo and the SABRE site blocked direct access. Coverage is thinnest for luxury hotels, luxury fashion houses and in-house teams, where agency credits are rarely published.
A34: Checks | B34: Every row has evidence text. Rows without a working link are marked Low. A few poaching signals came from the researchers' own knowledge and are tagged 'unverified, check before outreach'.
A35: Not included | B35: Media-buying-only mandates, except where the brand is luxury or premium.

Sheet Target list
A1: Rank | B1: Brand | C1: Priority | D1: Score (of 10) | E1: Fit pts | F1: Tier pts | G1: Timing pts (edit) | H1: Category | I1: Brand tier | J1: Parent company | K1: Current agency and mandate | L1: Held by group | M1: Recently lost by | N1: Why now (triggers) | O1: Poaching signals | P1: Key evidence | Q1: Latest source | R1: Confidence | S1: Source 1 | T1: Source 2 | U1: Mask360 relationship | V1: Owner | W1: Outreach status | X1: Next step | Y1: Notes
A2: 1 | B2: De Beers Forevermark | C2: =IF(U2<>"","Client",IF(D2>=9,"A",IF(D2>=7,"B","C"))) -> A | D2: =E2+F2+G2 -> 10 | E2: 4 | F2: 3 | G2: 3 | H2: Jewellery & watches | I2: Luxury | J2: De Beers Group | K2: Grey 82.5 (Ogilvy) (Creative, since 2024); Dentsu Creative Isobar (Integrated, since 2025) | L2: Dentsu, WPP | N2: Leadership change, Incumbent turmoil, Split roster | O2: Split mandates: Forevermark creative sits with Dentsu Creative Isobar; unit now appears as Grey 82.5 (WPP consolidation).; Split mandate; 2026 De Beers India campaigns carry no agency credit; 82.5 Communications folded into Grey 82.5 in Jun 2026; team and brand transition; Luxury retail rollout in India needs ongoing social, content and PR; Dentsu India offices searched by tax authorities Sep 2026; COO South Asia retired Aug 2026 and Chief Client Officer exited Nov 2025; De Beers splits work across two networks; PR and luxury events not assigned publicly. | P2: Won integrated creative mandate after multi-agency pitch (Mumbai); launched 'This One's For Me' with Delhi flagship in Oct 2025. | Q2: 2025-04 | R2: High | S2: https://www.storyboard18.com/brand-marketing/82-5-communications-wins-creative-mandate-for-de-beers-group-44868.htm | T2: https://www.medianews4u.com/82-5-communications-secures-creative-mandate-for-de-beers/ | W2: Not started
A3: 2 | B3: Four Seasons Mumbai and Bengaluru | C3: =IF(U3<>"","Client",IF(D3>=9,"A",IF(D3>=7,"B","C"))) -> A | D3: =E3+F3+G3 -> 10 | E3: 4 | F3: 3 | G3: 3 | H3: Luxury hospitality & travel | I3: Luxury | J3: Four Seasons Hotels | K3: None credited (in-house or unknown) | L3: Unknown | N3: Open mandates, No agency credited | O3: Likely handled by global brand team plus property PR; property social and F&B content are open doors. | P3: No India agency mandate or campaign credit found in Indian trade press 2024 to 2026. | Q3: 2026-09 | R3: Low | W3: Not started
A4: 3 | B4: Hilton India | C4: =IF(U4<>"","Client",IF(D4>=9,"A",IF(D4>=7,"B","C"))) -> A | D4: =E4+F4+G4 -> 10 | E4: 4 | F4: 3 | G4: 3 | H4: Luxury hospitality & travel | I4: Luxury | J4: Hilton Worldwide | K4: McCann India (Creative); TBWA\Lintas (Creative) | L4: Omnicom | N4: Leadership change, Incumbent turmoil | O4: Hilton's global marketing leader Mark Weinstein exited in Sep 2026; India wedding and luxury brands need local content beyond the global campaign.; Merged agency still settling; leadership now Govind Pandey (CEO) and Russell Barrett | P4: McCann India created Hilton's Deepika Padukone film in the 'It Matters Where You Stay' campaign. | Q4: 2026-09 | R4: Medium | S4: https://www.afaqs.com/news/advertising/hilton-wants-indias-hustlers-to-feel-at-home-enough-to-dance-just-ask-deepika-12186053 | T4: https://www.tbwaindia.com/ | W4: Not started
A5: 4 | B5: Hyatt India | C5: =IF(U5<>"","Client",IF(D5>=9,"A",IF(D5>=7,"B","C"))) -> A | D5: =E5+F5+G5 -> 10 | E5: 4 | F5: 3 | G5: 3 | H5: Luxury hospitality & travel | I5: Luxury | J5: Hyatt Hotels Corporation | K5: TBWA\Lintas (Creative); TBWA\Lintas (ex Lintas Live) (Social, since 2024) unconfirmed; Animal (Creative, since 2024) unconfirmed | L5: Independent, Omnicom | N5: Leadership change, Incumbent turmoil, Split roster | O5: Merged agency still settling; leadership now Govind Pandey (CEO) and Russell Barrett; Hyatt created a new President India and Southwest Asia role (Vikas Chawla, Mar 2026); Lintas absorbed into TBWA after Omnicom and IPG merger.; Project-based credits suggest no single AOR; new India president may consolidate. | P5: Lintas Live, a MullenLowe Lintas division, conceptualised the 'Hyatt Celebrates You' launch of Hyatt India's official Instagram with Vaani Kapoor. | Q5: 2026-09 | R5: Medium | S5: https://www.afaqs.com/news/advertising/hyatt-india-launches-official-instagram-page-with-vaani-kapoor-8449076 | T5: https://www.afaqs.com/news/advertising/hyatt-india-launches-new-fb-campaign-to-highlight-its-culinary-legacy-7777415 | W5: Not started
A6: 5 | B6: M3M India | C6: =IF(U6<>"","Client",IF(D6>=9,"A",IF(D6>=7,"B","C"))) -> A | D6: =E6+F6+G6 -> 10 | E6: 4 | F6: 3 | G6: 3 | H6: Real estate | I6: Luxury | J6: M3M Group | K6: None credited (in-house or unknown) | L6: Unknown | N6: Leadership change, Fresh budget or launch, No agency credited | O6: New marketing head with agency background; aggressive Gurugram luxury launches and sports properties (pickleball franchise). | P6: No agency credit found; M3M appointed Nitin Singh, ex DDB Mudra, as Head of Marketing in Jan 2026. | Q6: 2026-01 | R6: Low | S6: https://www.medianews4u.com/m3m-appoints-nitin-singh-as-head-of-marketing/ | W6: Not started
A7: 6 | B7: Oberoi Realty | C7: =IF(U7<>"","Client",IF(D7>=9,"A",IF(D7>=7,"B","C"))) -> A | D7: =E7+F7+G7 -> 10 | E7: 4 | F7: 3 | G7: 3 | H7: Real estate | I7: Luxury | J7: Oberoi Realty | K7: Madison Loop (ex Madison BMB) (Integrated, since 2023) | L7: Independent | N7: Leadership change, Incumbent turmoil | O7: Incumbent about 3 years; typical review window.; Three year incumbent on a luxury realty account; Madison BMB CEO Raj Nair exited in the merger; Shift to storytelling-led brand films; Ritz-Carlton serviced residences at Three Sixty West show appetite for ultra luxury content. | P7: Madison Loop won Oberoi Realty's integrated creative, digital, social and performance mandate after a competitive pitch. | Q7: 2026-06 | R7: Medium | S7: https://www.afaqs.com/news/advertising/madison-bmb-integrates-with-madison-loop | T7: https://www.afaqs.com/news/advertising/madison-loop-wins-the-integrated-account-of-oberoi-realty | W7: Not started
A8: 7 | B8: Rivaah by Tanishq | C8: =IF(U8<>"","Client",IF(D8>=9,"A",IF(D8>=7,"B","C"))) -> A | D8: =E8+F8+G8 -> 10 | E8: 4 | F8: 3 | G8: 3 | H8: Jewellery & watches | I8: Luxury | J8: Titan Company | K8: TBWA\Lintas (Creative); TBWA\Lintas (Integrated) | L8: Omnicom | N8: Leadership change, Incumbent turmoil | O8: Long-tenured Lintas relationship now running as TBWA\Lintas after network merger; integration period.; Bridal and destination-wedding content is specialist territory; MullenLowe retired; Lintas rebadged TBWA\Lintas Jan 2026; co-CEO Prateek Bharadwaj exit reported Feb 2026 | P8: TBWA\Lintas conceptualised Rivaah by Tanishq's Sep 2026 wedding campaign under CMO Pelki Tshering. | Q8: 2026-09 | R8: Medium | S8: https://www.afaqs.com/news/advertising/rivaah-by-tanishq-brings-many-stories-to-one-wedding-12540691 | W8: Not started
A9: 8 | B9: Sobha | C9: =IF(U9<>"","Client",IF(D9>=9,"A",IF(D9>=7,"B","C"))) -> A | D9: =E9+F9+G9 -> 10 | E9: 4 | F9: 3 | G9: 3 | H9: Real estate | I9: Luxury | J9: Sobha Ltd | K9: None credited (in-house or unknown) | L9: Unknown | N9: Leadership change, Fresh budget or launch, No agency credited | O9: New brand head within the last year typically reviews agencies; Sobha's design-led luxury positioning fits a luxury boutique. | P9: No agency credit found; Ashish Bajaj joined to lead brand and communications in Oct 2025. | Q9: 2025-10 | R9: Low | S9: https://www.afaqs.com/people-spotting/ashish-bajaj-to-lead-brand-and-communications-at-sobha-limited-10563656 | W9: Not started
A10: 9 | B10: The Leela Palaces, Hotels and Resorts | C10: =IF(U10<>"","Client",IF(D10>=9,"A",IF(D10>=7,"B","C"))) -> A | D10: =E10+F10+G10 -> 10 | E10: 4 | F10: 3 | G10: 3 | H10: Luxury hospitality & travel | I10: Luxury | J10: Schloss Bangalore (Brookfield) | K10: None credited (in-house or unknown) | L10: Unknown | N10: Leadership change, Incumbent turmoil, Fresh budget or launch, No agency credited | O10: CMO churn (Shweta Jain exit May 2025, Anjali Mehra now leading marketing); record FY26 results and expansion push (Apr 2026); 40-year brand storytelling; prime luxury poach target. | P10: Leela's social campaigns (Padmanabh Singh Nov 2024, Gauravi Kumari Dec 2025) carried no agency credit; CMO Shweta Jain left in May 2025. | Q10: 2025-06 | R10: Low | S10: https://www.socialsamosa.com/industry-updates/shweta-jain-steps-down-cmo-sales-officer-the-leela-palaces-9356489 | W10: Not started
A11: 10 | B11: BMW India | C11: =IF(U11<>"","Client",IF(D11>=9,"A",IF(D11>=7,"B","C"))) -> A | D11: =E11+F11+G11 -> 9 | E11: 3 | F11: 3 | G11: 3 | H11: Automotive | I11: Luxury | J11: BMW Group | K11: Contract Advertising (VML) (Integrated, since 2026); Lodestar UM (Omnicom Media) (Media, since 2022); Interactive Avenues (Omnicom Media) (Digital); PMG India (Hakuhodo) (Experiential) | L11: Hakuhodo, Omnicom, WPP | M11: Rediffusion (Integrated) | N11: Leadership change, Incumbent turmoil, Split roster | O11: New incumbent, low near-term poachability; but social, content, experiential and dealer content can be carved out.; Account moved 2026-01 from Rediffusion; marketing director Vitesh Barar; WPP creative restructuring ongoing; Newly won in pitch; VML India creative head who oversaw Contract (Kalpesh Patankar) exited Aug 2026; Fresh pitch Jan 2026; MINI digital split out to SW Network; WPP network restructuring.; IPG Mediabrands retired into Omnicom Media post merger; creative just moved, media could follow; IPG Mediabrands folded into Omnicom Media; IA creative team integration under way; luxury auto; Experiential only; content and social separate; Brand just ran a review; signals willingness to change partners.; Account moved 2026-01 after about 4 years | P11: BMW India awarded integrated creative mandate (mainline plus digital) to VML's Contract Advertising after a competitive pitch, replacing Rediffusion. | Q11: 2026-08 | R11: High | S11: https://www.storyboard18.com/agency-news/exclusive-bmw-india-appoints-vmls-contract-advertising-india-as-creative-agency-87842.htm | T11: https://www.adgully.com/post/11327/contract-advertising-india-wins-integrated-creative-mandate-for-bmw-india | W11: Not started
A12: 11 | B12: Diageo India Reserve portfolio | C12: =IF(U12<>"","Client",IF(D12>=9,"A",IF(D12>=7,"B","C"))) -> A | D12: =E12+F12+G12 -> 9 | E12: 3 | F12: 3 | G12: 3 | H12: Alcobev | I12: Luxury | J12: Diageo India | K12: The Glitch (VML) (Integrated, since 2018) unconfirmed | L12: WPP | N12: Incumbent turmoil, Long tenure | O12: The Glitch shows no trade press activity after Apr 2024 and theglitch.in no longer resolves; likely absorbed into VML; Black & White work credited to Saatchi & Saatchi India at Storyboard18 Awards 2026 | P12: The Glitch expanded to a 360 degree mandate for Diageo India's premium, luxury and reserve brands in Feb 2020. | Q12: 2020-02 | R12: Medium | S12: https://www.medianews4u.com/the-glitch-expands-their-integrated-creative-portfolio-with-the-addition-of-diageo-indias-premium-luxury-and-reserve-brands/ | W12: Not started
A13: 12 | B13: Ducati India | C13: =IF(U13<>"","Client",IF(D13>=9,"A",IF(D13>=7,"B","C"))) -> A | D13: =E13+F13+G13 -> 9 | E13: 3 | F13: 3 | G13: 3 | H13: Automotive | I13: Luxury | J13: Ducati (Audi AG) | K13: Burson India (PR, since 2024) | L13: WPP | N13: Leadership change, Incumbent turmoil | O13: WPP hired Goldman Sachs in Apr 2026 to explore a sale of Burson; New head of marketing 2026-05 | P13: Ducati India elevated Amit Chauhan to head of marketing. | Q13: 2026-05 | R13: High | S13: https://www.medianews4u.com/ducati-india-appoints-burson-as-strategic-communications-partner/ | T13: https://www.afaqs.com/people-spotting/ducati-india-elevates-amit-chauhan-to-head-of-marketing-11805878 | W13: Not started
A14: 13 | B14: Kama Ayurveda | C14: =IF(U14<>"","Client",IF(D14>=9,"A",IF(D14>=7,"B","C"))) -> A | D14: =E14+F14+G14 -> 9 | E14: 3 | F14: 3 | G14: 3 | H14: Beauty & personal care | I14: Luxury | J14: Puig (majority) | K14: None credited (in-house or unknown) | L14: Unknown | N14: Leadership change, No agency credited | O14: Former marketing head moved to Heads Up For Tails (May 2026) | P14: Medianews4u search for Kama Ayurveda returned no agency credit. | Q14: 2026-09 | R14: Low | W14: Not started
A15: 14 | B15: Mercedes-Benz India | C15: =IF(U15<>"","Client",IF(D15>=9,"A",IF(D15>=7,"B","C"))) -> A | D15: =E15+F15+G15 -> 9 | E15: 3 | F15: 3 | G15: 3 | H15: Automotive | I15: Luxury | J15: Mercedes-Benz Group | K15: Adfactors PR (PR, since 2025); BBDO India (Integrated); PMG India (Hakuhodo) (Experiential); BBDO India (Creative); Social Beat (Cheil) (Social) unconfirmed | L15: Cheil, Hakuhodo, Independent, Omnicom | N15: Leadership change, Incumbent turmoil, Split roster | O15: New head of marketing Nandita Godbole elevated Jul 2026 (afaqs); creative, social and experiential partners not publicly mapped.; Dedicated Team X unit; luxury social, content and experiential could be carved out; BBDO India CEO Suraja Kishore exited Apr 2025; Jitender Dabas named BBDO Group CEO Feb 2026 as Mudra and Ulka folded in; Experiential only; social, content and PR are separate opportunities; New head of marketing Nandita Godbole (Jul 2026, succeeding Amrit Baid); marketing budget kept flat despite record sales; festive Dream Days campaign carried no agency credit.; New head of marketing from 2026-09 with AI and data focus; rival BMW moved creative 2026-01; New sports property 2026-07 needing content and experiential support; Social Beat was acquired by Cheil SWA Group (Nov 2025); post-acquisition integration and senior exits (AVP Dhruhi Sethi left Jan 2026). | P15: Team X BBDO India made the Sep 2025 'Dream Days' festive campaign and the Sep 2026 '140 Years. 140 Places.' India leg. | Q15: 2026-09 | R15: High | S15: https://www.adgully.com/post/611/mercedes-benz-india-awards-pr-mandate-to-adfactors-pr | T15: https://www.afaqs.com/people-spotting/mercedes-benz-india-elevates-nandita-godbole-as-head-of-marketing-12159853 | W15: Not started
A16: 15 | B16: MINI India | C16: =IF(U16<>"","Client",IF(D16>=9,"A",IF(D16>=7,"B","C"))) -> A | D16: =E16+F16+G16 -> 9 | E16: 3 | F16: 3 | G16: 3 | H16: Automotive | I16: Luxury | J16: BMW Group | K16: SW Network (Sociowash) (Digital, since 2026); VML India (Integrated) | L16: Independent, WPP | N16: Leadership change, Split roster, Long tenure | O16: Recently awarded; lifestyle content and influencer layers still open.; Appointed 2026-01 with no pitch disclosed; sister brand BMW moved creative the same month; BMW India mainline moved to Contract (WPP) in Jan 2026; MINI digital sits separately, split mandates; BMW India moved integrated communications to Contract Advertising the same week (Jan 2026), group roster in flux.; Split mandate inside BMW Group India (BMW creative with Contract); PR and experiential not assigned publicly.; VML India Group CCO Kalpesh Patankar exited Aug 2026 (to Leo Gulf) and CSO Pinaki Bhattacharya exited early 2026 after 16 years | P16: SW Network appointed digital and creative agency for MINI India covering strategy, campaigns and lifestyle content, handled from Delhi. | Q16: 2026-06 | R16: High | S16: https://www.storyboard18.com/agency-news/sw-network-wins-full-digital-mandate-for-mini-india-87868.htm | T16: https://www.afaqs.com/news/newbizwins/sw-network-wins-digital-creative-mandate-for-mini-india-11012093 | W16: Not started
A17: 16 | B17: Porsche India | C17: =IF(U17<>"","Client",IF(D17>=9,"A",IF(D17>=7,"B","C"))) -> A | D17: =E17+F17+G17 -> 9 | E17: 3 | F17: 3 | G17: 3 | H17: Automotive | I17: Luxury | J17: Porsche AG | K17: AdGlobal360 (Hakuhodo) (Digital); PMG India (Hakuhodo) (Experiential) | L17: Hakuhodo | N17: Leadership change, Split roster, Fresh budget or launch | O17: Split: PMG India handles Porsche experiential; New brand director within the last six months; Porsche globally cutting costs, so efficient local content partners appeal. | P17: AdGlobal360 won cross-channel marketing award for Porsche at e4m Automotive Marketing Awards 2026. | Q17: 2026-05 | R17: Medium | S17: https://www.hakuhodo-global.com/news/hakuhodo-india-network-secures-16-prestigious-awards-at-e4m-automotive-marketing-awards-2026.html | T17: https://www.afaqs.com/people-spotting/škoda-india-appoints-ashutosh-dixit-as-brand-director-of-porsche-india-11802850 | W17: Not started
A18: 17 | B18: Sazerac India (Paul John, Buffalo Trace) | C18: =IF(U18<>"","Client",IF(D18>=9,"A",IF(D18>=7,"B","C"))) -> A | D18: =E18+F18+G18 -> 9 | E18: 3 | F18: 3 | G18: 3 | H18: Alcobev | I18: Luxury | J18: Sazerac | K18: None credited (in-house or unknown) | L18: Unknown | N18: Leadership change, No agency credited | O18: New MD 2026-09 from Bimbo and PepsiCo | P18: Kunal Sharma joined Sazerac as MD India, overseeing Paul John, Buffalo Trace, Weller and Fireball. | Q18: 2026-09 | R18: High | S18: https://www.storyboard18.com/brand-makers/kunal-sharma-named-sazerac-india-managing-director-ws-l-110645.htm | W18: Not started
A19: 18 | B19: DLF | C19: =IF(U19<>"","Client",IF(D19>=9,"A",IF(D19>=7,"B","C"))) -> A | D19: =E19+F19+G19 -> 9 | E19: 4 | F19: 3 | G19: 2 | H19: Real estate | I19: Luxury | J19: DLF Ltd | K19: None credited (in-house or unknown) | L19: Unknown | N19: Fresh budget or launch, No agency credited | O19: Ultra luxury Gurugram launches sell on project marketing; luxury launch films and HNI content are pitchable per project; no visible incumbent. | P19: No creative or social agency credit found for DLF homes 2024 to 2026; DLF Malls' Summer Up campaign (May 2026) carried no agency credit; last public digital mandate was Envigo in 2015. | Q19: 2026-05 | R19: Low | S19: https://www.campaignindia.in/article/dlf-malls-launches-phygital-summer-up-campaign/4pvgt96ejphfhssc00m9ec3vmp | W19: Not started
A20: 19 | B20: Elan Group | C20: =IF(U20<>"","Client",IF(D20>=9,"A",IF(D20>=7,"B","C"))) -> A | D20: =E20+F20+G20 -> 9 | E20: 4 | F20: 3 | G20: 2 | H20: Real estate | I20: Luxury | J20: Elan Group | K20: None credited (in-house or unknown) | L20: Unknown | N20: Fresh budget or launch, No agency credited | O20: Big celebrity bet without visible agency; luxury Gurugram launches. | P20: No agency credit found; Elan signed Shah Rukh Khan as brand ambassador (Feb 2025) and hired an AGM Brand Marketing (Jul 2025). | Q20: 2025-02 | R20: Low | S20: https://www.afaqs.com/news/mktg/elan-group-onboards-shah-rukh-khan-as-brand-ambassador-8750776 | W20: Not started
A21: 20 | B21: Ethos Watches | C21: =IF(U21<>"","Client",IF(D21>=9,"A",IF(D21>=7,"B","C"))) -> A | D21: =E21+F21+G21 -> 9 | E21: 4 | F21: 3 | G21: 2 | H21: Jewellery & watches | I21: Luxury | J21: Ethos Ltd | K21: None credited (in-house or unknown) | L21: Unknown | N21: Fresh budget or launch, No agency credited | O21: Listed via 2024 IPO; expanding luxury watch retail; no visible agency | P21: Searched medianews4u for Ethos Watches; no agency appointment or campaign credit surfaced. | Q21: 2026-09 | R21: Low | W21: Not started
A22: 21 | B22: Experion Developers | C22: =IF(U22<>"","Client",IF(D22>=9,"A",IF(D22>=7,"B","C"))) -> A | D22: =E22+F22+G22 -> 9 | E22: 4 | F22: 3 | G22: 2 | H22: Real estate | I22: Luxury | J22: Experion Group | K22: None credited (in-house or unknown) | L22: Unknown | N22: Fresh budget or launch, No agency credited | O22: Leadership reshuffle; luxury Gurugram launches. | P22: No agency credit found; hired a VP Communications (Jan 2025) and named a deputy CEO. | Q22: 2025-01 | R22: Low | S22: https://www.afaqs.com/people-spotting/himanshu-raj-joins-juniper-green-energy-experion-developers-as-vp-communications-8598890 | W22: Not started
A23: 22 | B23: Galeries Lafayette India | C23: =IF(U23<>"","Client",IF(D23>=9,"A",IF(D23>=7,"B","C"))) -> A | D23: =E23+F23+G23 -> 9 | E23: 4 | F23: 3 | G23: 2 | H23: Fashion & luxury retail | I23: Luxury | J23: Galeries Lafayette | K23: None credited (in-house or unknown) | L23: Unknown | N23: Fresh budget or launch, No agency credited | O23: New brand marketing head 2026-08 ahead of India build out; agencies not disclosed | P23: Noopur Khandekar, ex SVP at Tilt Brand Solutions, joined as head of brand marketing for Galeries Lafayette India. | Q23: 2026-08 | R23: High | S23: https://www.afaqs.com/people-spotting/noopur-khandekar-joins-galeries-lafayette-india-as-brand-marketing-head-12391643 | W23: Not started
A24: 23 | B24: ITC Hotels | C24: =IF(U24<>"","Client",IF(D24>=9,"A",IF(D24>=7,"B","C"))) -> A | D24: =E24+F24+G24 -> 9 | E24: 4 | F24: 3 | G24: 2 | H24: Luxury hospitality & travel | I24: Luxury | J24: ITC Hotels Ltd | K24: Actimedia PR (PR, since 2021) unconfirmed | L24: Independent | N24: Incumbent turmoil | O24: New F&B marketing head 2026-08; Five year old PR relationship; ITC Hotels demerged and listed, acquiring Zuri Kumarakom and GHK (2026), new F&B marketing head (Aug 2026).; Newly independent listed company building its own brand voice; 'Responsible Luxury' platform, new acquisitions and Mementos luxury tier need premium content. | P24: ITC Hotels appointed Rajiv Singh as head of food and beverages marketing. | Q24: 2026-08 | R24: High | S24: https://www.afaqs.com/people-spotting/itc-hotels-appoints-rajiv-singh-as-head-food-beverages-marketing-12250848 | T24: https://www.exchange4media.com/pr-and-corporate-communication-news/itc-hotels-ropes-in-actimedia-as-pr-and-communications-partner-113939.html | W24: Not started
A25: 24 | B25: Krishna GVK Hotels (ex Taj GVK) | C25: =IF(U25<>"","Client",IF(D25>=9,"A",IF(D25>=7,"B","C"))) -> A | D25: =E25+F25+G25 -> 9 | E25: 4 | F25: 3 | G25: 2 | H25: Luxury hospitality & travel | I25: Luxury | J25: GVK Group | K25: None credited (in-house or unknown) | L25: Unknown | N25: Fresh budget or launch, No agency credited | O25: Full rebrand and identity launch across Hyderabad and Chennai hotels: new brand, new agency need. | P25: Taj GVK Hotels is to become Krishna GVK Hotels, exiting the Taj name (Jul 2026). | Q25: 2026-07 | R25: Low | S25: https://www.storyboard18.com/brand-marketing/taj-gvk-hotels-to-become-krishna-gvk-hotels-taj-gvk-hotels-to-become-krishna-gvk-hotels-ws-l-106223.htm | W25: Not started
A26: 25 | B26: Manish Malhotra | C26: =IF(U26<>"","Client",IF(D26>=9,"A",IF(D26>=7,"B","C"))) -> A | D26: =E26+F26+G26 -> 9 | E26: 4 | F26: 3 | G26: 2 | H26: Fashion & luxury retail | I26: Luxury | J26: Manish Malhotra (Reliance Brands stake) | K26: None credited (in-house or unknown) | L26: Unknown | N26: Fresh budget or launch, No agency credited | O26: Reliance Brands-backed expansion; in-house content | P26: No external agency credit surfaced for Manish Malhotra. | Q26: 2026-09 | R26: Low | W26: Not started
A27: 26 | B27: Reliance Brands (luxury franchise portfolio) | C27: =IF(U27<>"","Client",IF(D27>=9,"A",IF(D27>=7,"B","C"))) -> A | D27: =E27+F27+G27 -> 9 | E27: 4 | F27: 3 | G27: 2 | H27: Fashion & luxury retail | I27: Luxury | J27: Reliance Retail | K27: None credited (in-house or unknown) | L27: Unknown | N27: Fresh budget or launch, No agency credited | O27: 80+ franchise brands; local launch and PR briefs brand by brand | P27: No Reliance Brands agency appointment surfaced; international franchises typically use global brand assets. | Q27: 2026-09 | R27: Low | W27: Not started
A28: 27 | B28: The Leela Palace Jaipur | C28: =IF(U28<>"","Client",IF(D28>=9,"A",IF(D28>=7,"B","C"))) -> A | D28: =E28+F28+G28 -> 9 | E28: 4 | F28: 3 | G28: 2 | H28: Luxury hospitality & travel | I28: Luxury | J28: The Leela (Schloss Bangalore) | K28: Quirk Head (Digital) unconfirmed | L28: Independent | N28: Open mandates | O28: Property-level digital; Leela brand campaigns led by CMSO Shweta Jain with no agency credited (afaqs Nov 2024). | P28: Quirk Head website lists The Leela Palace Jaipur among its luxury hospitality clients. | Q28: 2026-09 | R28: Medium | S28: https://quirkhead.ae/ | W28: Not started
A29: 28 | B29: Tribeca Developers (Trump Towers India) | C29: =IF(U29<>"","Client",IF(D29>=9,"A",IF(D29>=7,"B","C"))) -> A | D29: =E29+F29+G29 -> 9 | E29: 4 | F29: 3 | G29: 2 | H29: Real estate | I29: Luxury | J29: Tribeca Developers | K29: None credited (in-house or unknown) | L29: Unknown | N29: Fresh budget or launch, No agency credited | O29: Ultra luxury branded residences launched city by city; launch content per project. | P29: No agency relationship found in Indian trade press for Tribeca or Trump Towers India. | Q29: 2026-09 | R29: Low | W29: Not started
A30: 29 | B30: Vianaar | C30: =IF(U30<>"","Client",IF(D30>=9,"A",IF(D30>=7,"B","C"))) -> A | D30: =E30+F30+G30 -> 9 | E30: 4 | F30: 3 | G30: 2 | H30: Real estate | I30: Luxury | J30: Vianaar | K30: PROHED (Performance, since 2026) | L30: Independent | N30: Open mandates | O30: Performance only 2026-03; brand creative and content not disclosed; Performance only; brand film, social and content for a design-led luxury developer unassigned publicly. | P30: PROHED won the performance marketing mandate for Vianaar. | Q30: 2026-03 | R30: High | S30: https://www.afaqs.com/news/newbizwins/prohed-bags-performance-marketing-mandate-for-vianaar-11220895 | W30: Not started
A31: 30 | B31: Whiteland Corporation | C31: =IF(U31<>"","Client",IF(D31>=9,"A",IF(D31>=7,"B","C"))) -> A | D31: =E31+F31+G31 -> 9 | E31: 4 | F31: 3 | G31: 2 | H31: Real estate | I31: Luxury | J31: Whiteland Corporation | K31: None credited (in-house or unknown) | L31: Unknown | N31: Fresh budget or launch, No agency credited | O31: Gurugram luxury launches with no visible agency support. | P31: No agency relationship found in Indian trade press. | Q31: 2026-09 | R31: Low | W31: Not started
A32: 31 | B32: Adani Realty | C32: =IF(U32<>"","Client",IF(D32>=9,"A",IF(D32>=7,"B","C"))) -> A | D32: =E32+F32+G32 -> 9 | E32: 4 | F32: 2 | G32: 3 | H32: Real estate | I32: Premium | J32: Adani Group | K32: 22feet Tribal Worldwide (Creative); Mirum India (VML) (Digital, since 2023) unconfirmed | L32: Omnicom, WPP | N32: Incumbent turmoil, Split roster, Fresh budget or launch | O32: Adani uses multiple agencies; Kinnect and 22feet leadership merged under Chandni Shah; unit says it will take only five new clients in 2026; Project scope; no recent credit visible; Adani Group put a Rs 500 to 600 crore media mandate up for review (Dec 2025); NCR expansion team newly built. | P32: Adani Realty and 22feet India released a Ganesh festival film on Bappa's homecoming in Sep 2026. | Q32: 2026-09 | R32: High | S32: https://campaignbriefasia.com/2026/09/23/adani-realty-and-22feet-india-celebrate-the-journey-of-bappas-homecoming/ | T32: https://www.medianews4u.com/adani-realty-collaborates-with-mirum-india-for-its-vr-offering/ | W32: Not started
A33: 32 | B33: Arvind SmartSpaces | C33: =IF(U33<>"","Client",IF(D33>=9,"A",IF(D33>=7,"B","C"))) -> A | D33: =E33+F33+G33 -> 9 | E33: 4 | F33: 2 | G33: 3 | H33: Real estate | I33: Premium | J33: Arvind Group | K33: None credited (in-house or unknown) | L33: Unknown | N33: Leadership change, No agency credited | O33: New head of marketing 2026-09 | P33: Arvind SmartSpaces appointed Ankit Dave as head of marketing. | Q33: 2026-09 | R33: High | S33: https://www.afaqs.com/people-spotting/arvind-smartspaces-appoints-ankit-dave-as-head-of-marketing-12583232 | W33: Not started
A34: 33 | B34: BIBA | C34: =IF(U34<>"","Client",IF(D34>=9,"A",IF(D34>=7,"B","C"))) -> A | D34: =E34+F34+G34 -> 9 | E34: 4 | F34: 2 | G34: 3 | H34: Fashion & luxury retail | I34: Premium | J34: Biba Apparels | K34: Famous Innovations (Creative); Dentsu Creative India (Creative, since 2022) unconfirmed | L34: Dentsu, Independent | M34: BBH India (ex Publicis India) (Creative) | N34: Leadership change, Incumbent turmoil | O34: Taproot brand retired in 2022 merger; later BIBA campaign credited to iProspect; Moved to Taproot Dentsu | P34: Biba is listed among Famous Innovations' existing clients. | Q34: 2026-04 | R34: High | S34: https://www.afaqs.com/news/advertising/famous-innovations-wins-5-major-mandates-in-h2-strengthens-geographical-expansion-11727022 | T34: https://www.medianews4u.com/taproot-dentsu-wins-creative-mandate-for-biba/ | W34: Not started
A35: 34 | B35: Brigade Group | C35: =IF(U35<>"","Client",IF(D35>=9,"A",IF(D35>=7,"B","C"))) -> A | D35: =E35+F35+G35 -> 9 | E35: 4 | F35: 2 | G35: 3 | H35: Real estate | I35: Premium | J35: Brigade Enterprises | K35: Webenza (Digital) unconfirmed; Social Beat (Cheil) (Performance) unconfirmed | L35: Cheil, Independent | N35: Leadership change, Incumbent turmoil, Split roster | O35: Brigade also appears on Social Beat's work page; split or rotating roster.; Bengaluru luxury, office and hospitality portfolio; no visible incumbent in trade press.; Social Beat was acquired by Cheil SWA Group (Nov 2025); post-acquisition integration and senior exits (AVP Dhruhi Sethi left Jan 2026). | P35: Webenza's homepage features a Brigade Group case study and logo. | Q35: 2026-09 | R35: Medium | S35: https://www.webenza.com/ | T35: https://www.socialbeat.in/work/ | W35: Not started
A36: 35 | B36: Club Mahindra (Club M) | C36: =IF(U36<>"","Client",IF(D36>=9,"A",IF(D36>=7,"B","C"))) -> A | D36: =E36+F36+G36 -> 9 | E36: 4 | F36: 2 | G36: 3 | H36: Luxury hospitality & travel | I36: Premium | J36: Mahindra Holidays & Resorts India | K36: None credited (in-house or unknown) | L36: Unknown | N36: Leadership change, Incumbent turmoil, No agency credited | O36: Rebrand plus CMO exit plus new group CEO for Real Estate and Hospitality (Aug 2026) plus adex cut 26% in FY25: classic moment for a new agency. | P36: No agency credit found; CMO Pratik Mazumder quit in Jun 2025 and the brand is rebranding to Club M with a Rs 1,000 crore leisure hospitality push. | Q36: 2025-11 | R36: Low | S36: https://www.storyboard18.com/brand-marketing/club-mahindra-to-rebrand-as-club-m-enters-leisure-hospitality-with-rs-1000-crore-investment-84498.htm | W36: Not started
A37: 36 | B37: Enamor | C37: =IF(U37<>"","Client",IF(D37>=9,"A",IF(D37>=7,"B","C"))) -> A | D37: =E37+F37+G37 -> 9 | E37: 4 | F37: 2 | G37: 3 | H37: Fashion & luxury retail | I37: Premium | J37: Gokaldas Intimatewear | K37: Tilt Brand Solutions (Integrated, since 2025); The Glitch (VML) (Integrated, since 2022) unconfirmed | L37: Independent, WPP | M37: BBH India (ex Publicis India) (Creative); Propagate India (Publicis) (Digital) | N37: Leadership change, Incumbent turmoil | O37: CBO Hari Krishnan exited Tilt in Oct 2025, servicing leadership changed; Tilt CBO Hari Krishnan exited Oct 2025; Tilt added Santoor AOR Apr 2026 (bandwidth).; The Glitch shows no trade press activity after Apr 2024 and theglitch.in no longer resolves; likely absorbed into VML; Moved to Tilt Brand Solutions; brand has changed agencies three times since 2022 | P37: Enamor appointed Tilt Brand Solutions as its brand and communications AOR. | Q37: 2025-03 | R37: High | S37: https://www.afaqs.com/news/newbizwins/enamor-appoints-tilt-brand-solutions-as-its-brand-communications-aor-8888963 | T37: https://www.medianews4u.com/enamor-names-tilt-brand-solutions-as-brand-communications-aor/ | W37: Not started
A38: 37 | B38: Ethnix by Raymond | C38: =IF(U38<>"","Client",IF(D38>=9,"A",IF(D38>=7,"B","C"))) -> A | D38: =E38+F38+G38 -> 9 | E38: 4 | F38: 2 | G38: 3 | H38: Fashion & luxury retail | I38: Premium | J38: Raymond Lifestyle Ltd | K38: Mudra (ex DDB Mudra, BBDO Group) (Creative, since 2022) unconfirmed | L38: Omnicom | N38: Incumbent turmoil, Split roster | O38: No recent credit; wedding-wear competition with Manyavar and Tasva; Premium ethnic wear sub-brand; DDB brand retired Jan 2026 and DDB Mudra split across McCann, BBDO Group (Mudra) and TBWA\Lintas; destination of this account not announced | P38: DDB Mudra Group created Ethnix by Raymond's family-themed campaign (Nov 2022). | Q38: 2022-11 | R38: Medium | S38: https://www.medianews4u.com/ethnix-by-raymond-celebrates-family-and-fashion-in-its-latest-campaign/ | T38: https://www.afaqs.com/news/advertising/ddb-mudra-wins-raymonds-integrated-aor-mandate | W38: Not started
A39: 38 | B39: Foot Locker India | C39: =IF(U39<>"","Client",IF(D39>=9,"A",IF(D39>=7,"B","C"))) -> A | D39: =E39+F39+G39 -> 9 | E39: 4 | F39: 2 | G39: 3 | H39: Fashion & luxury retail | I39: Premium | J39: Metro Brands | K39: Scribbld (Social, since 2025); SW Network (Sociowash) (Creative, since 2025); SW Network (Sociowash) (Integrated, since 2025) | L39: Independent | N39: Incumbent turmoil, Split roster | O39: Metro Brands gave Foot Locker mainline creative to SW Network two months later, possible consolidation risk; Split with SW Network, which took Foot Locker mainline creative in Nov 2025.; SW Network won Foot Locker mandates two months later; overlap or churn.; Scribbld holds Foot Locker digital and social since Sep 2025, split mandate; Scribbld had Foot Locker digital and social from Sep 2025; Metro Brands reshuffles quickly. | P39: SW Network won mainline creative duties for Foot Locker and digital creative for FILA from Metro Brands. | Q39: 2025-11 | R39: High | S39: https://www.afaqs.com/news/newbizwins/scribbld-wins-digital-and-social-media-mandate-for-foot-locker-india-10279212 | T39: https://www.medianews4u.com/scribbld-wins-digital-and-social-media-mandate-for-foot-locker-india/ | W39: Not started
A40: 39 | B40: Godrej Properties | C40: =IF(U40<>"","Client",IF(D40>=9,"A",IF(D40>=7,"B","C"))) -> A | D40: =E40+F40+G40 -> 9 | E40: 4 | F40: 2 | G40: 3 | H40: Real estate | I40: Premium | J40: Godrej Group | K40: Ogilvy India (Digital, since 2021) unconfirmed; Madison Loop (ex Madison BMB) (Integrated) unconfirmed; Gozoop (now YAAP) (Digital, since 2023) unconfirmed | L40: Independent, WPP | N40: Leadership change, Incumbent turmoil, Fresh budget or launch, Split roster | O40: No visible Ogilvy work since 2021; real estate digital scope may be open; Gozoop merged into YAAP in 2026; ORM-only scope leaves creative and social open.; Targeting Rs 40,000 crore of launches in FY26 across new cities; experiential and launch content briefs per project; MD and CEO Gaurav Pandey reappointed (Aug 2025). | P40: Gozoop Hawk bagged the digital customer service (ORM) mandate for Godrej Properties. | Q40: 2026-01 | R40: Medium | S40: https://www.medianews4u.com/godrej-properties-launches-its-first-digital-brand-campaign/ | T40: https://www.afaqs.com/news/advertising/madison-bmb-integrates-with-madison-loop | W40: Not started
...

Sheet In play now
A1: Date | B1: Brand | C1: Category | D1: Brand tier | E1: What is happening | F1: Agency involved | G1: Agency status | H1: Mandate | I1: Evidence | J1: Source | K1: Confidence
A2: 2026-09 | B2: DeVANS (Godfather, Six Fields, GianChand) | C2: Alcobev | D2: Luxury | E2: Appointed 2026-09 with no pitch disclosed; PR, film and experiential not assigned in sources | F2: INNOCEAN India | G2: Won recently | H2: Digital | I2: INNOCEAN India won digital strategy, creative direction and social for GianChand Single Malt across India and international markets. | J2: https://www.afaqs.com/news/newbizwins/innocean-india-wins-digital-and-social-mandate-for-gianchand-single-malt-12539501 | K2: High
A3: 2026-09 | B3: Sazerac India (Paul John, Buffalo Trace) | C3: Alcobev | D3: Luxury | E3: New MD 2026-09 from Bimbo and PepsiCo | F3: Unknown or in-house | G3: Unclear | H3: Integrated | I3: Kunal Sharma joined Sazerac as MD India, overseeing Paul John, Buffalo Trace, Weller and Fireball. | J3: https://www.storyboard18.com/brand-makers/kunal-sharma-named-sazerac-india-managing-director-ws-l-110645.htm | K3: High
A4: 2026-09 | B4: The Diamond Collective (Natural Diamond Council) | C4: Jewellery & watches | D4: Luxury | E4: Rebrand and new strategy 2026-09 with new global campaigns; agencies not named | F4: Unknown or in-house | G4: Unclear | H4: Integrated | I4: Natural Diamond Council relaunched as The Diamond Collective under new CEO Amber Pepper, with a Diamond Desire Index launching in India. | J4: https://www.manifest-media.in/marketing/240926/natural-diamond-council-relaunches-as-the-diamond-collective-with-new.html | K4: High
A5: 2026-09 | B5: VinFast India | C5: Automotive | D5: Premium | E5: PR appointed 2026-09; sister company GSM ran a creative and media pitch 2026-01 | F5: Boomerang Collaborations | G5: Won recently | H5: PR | I5: Campaign India reports VinFast India awarded its communications mandate to Boomerang Collaborations with Velocity Fintrust. | J5: https://www.campaignindia.in/article/pitch-update-coca-cola-mastercard-vinfast-sleepwell-and-more/42wq85ph1ex6qsf9ngpgb9ahxk | K5: High
A6: 2026-09 | B6: 4700BC | C6: Premium F&B & QSR | D6: Premium | E6: Rebrand underway 2026-09; launch campaign and social likely to follow | F6: Pollinate Labs | G6: Won recently | H6: Creative | I6: Pollinate Labs won the rebranding mandate for gourmet popcorn brand 4700BC. | J6: https://www.afaqs.com/news/newbizwins/pollinate-labs-wins-the-rebranding-mandate-for-4700bc-12506207 | K6: High
A7: 2026-09 | B7: Air India | C7: Aviation | D7: Premium | E7: Leadership reset 2026-09 (new CEO-designate, comms head exit); media moved 2026-06; creative incumbent not verified | F7: Unknown or in-house | G7: Unclear | H7: Creative | I7: Air India's global communications head Partha Ghosh exited after CEO Campbell Wilson's exit; CEO-designate Tewolde Gebremariam is charting the next phase. | J7: https://www.afaqs.com/people-spotting/partha-ghosh-exits-air-india-after-three-and-a-half-years-12558443 | K7: Medium
A8: 2026-09 | B8: Arvind Limited | C8: Fashion & luxury retail | D8: Premium | E8: New comms head 2026-09 | F8: Unknown or in-house | G8: Unclear | H8: PR | I8: Arvind appointed Swagat Lakku as head of corporate communications. | J8: https://www.afaqs.com/corporate-communications-and-pr/arvind-appoints-swagat-lakku-as-head-of-corporate-communications-12588593 | K8: High
A9: 2026-09 | B9: Arvind SmartSpaces | C9: Real estate | D9: Premium | E9: New head of marketing 2026-09 | F9: Unknown or in-house | G9: Unclear | H9: Integrated | I9: Arvind SmartSpaces appointed Ankit Dave as head of marketing. | J9: https://www.afaqs.com/people-spotting/arvind-smartspaces-appoints-ankit-dave-as-head-of-marketing-12583232 | K9: High
A10: 2026-09 | B10: CMF by Nothing | C10: Consumer tech & D2C | D10: Premium | E10: Brand spin-off 2026-09; Nothing's India marketing lead left for DailyObjects 2026-09 | F10: Unknown or in-house | G10: Unclear | H10: Integrated | I10: Nothing spun off CMF in India as a separate brand, per Storyboard18. | J10: https://www.storyboard18.com/brand-makers/nothing-ceo-india-needs-engineering-not-just-manufacturing-ws-l-111110.htm | K10: Medium
A11: 2026-09 | B11: DailyObjects | C11: Consumer tech & D2C | D11: Premium | E11: New Global CMO Zeenah Vilcassim joined 2026-09 from Nothing | F11: Unknown or in-house | G11: Unclear | H11: Integrated | I11: DailyObjects appointed Zeenah Vilcassim, who led marketing for Nothing in India, as Global CMO. | J11: https://www.afaqs.com/people-spotting/dailyobjects-appoints-zeenah-vilcassim-as-global-chief-marketing-officer-12570725 | K11: High
A12: 2026-09 | B12: IndiGo | C12: Aviation | D12: Premium | E12: New content and creative head 2026-09 | F12: Unknown or in-house | G12: Unclear | H12: Integrated | I12: IndiGo appointed Mayank Kumar as head of content and creative, marketing. | J12: https://www.afaqs.com/people-spotting/indigo-appoints-mayank-kumar-as-head-of-content-creative-marketing-12514196 | K12: High
... A126: 2024-12 | B126: Kotak Mahindra Bank | C126: BFSI & wealth | D126: Premium | E126: Review signal plus leadership change in marketing (Jul 2026). | F126: Wavemaker (WPP Media) | G126: In review | H126: Media | I126: Kotak Mahindra Group's Rs 100 to 150 crore media account, held by Wavemaker, was reported as evaluating partners in 2024. | J126: https://www.storyboard18.com/advertising/biz-breaks-major-account-moves-and-pitches-of-2024-51970.htm | K126: Medium

Sheet Agency roster
A1: Agency (current name) | B1: Group | C1: Type | D1: Relationships found | E1: Luxury accounts | F1: Premium accounts | G1: Luxury and premium accounts held | H1: Other accounts held | I1: Recently lost | J1: Also reported as
A2: Ogilvy India | B2: WPP | C2: Network creative | D2: =COUNTIF('All relationships'!$A$2:$A$1227,A2) -> 42 | E2: =COUNTIFS('All relationships'!$A$2:$A$1227,A2,'All relationships'!$H$2:$H$1227,"Luxury",'All relationships'!$K$2:$K$1227,"<>Recently lost") -> 2 | F2: =COUNTIFS('All relationships'!$A$2:$A$1227,A2,'All relationships'!$H$2:$H$1227,"Premium",'All relationships'!$K$2:$K$1227,"<>Recently lost") -> 12 | G2: Aqua Plumbings (Plumber Bathware, Aquini) (L), Asian Paints Emporio (L), Adani Airports, Allen Solly, Asian Paints, Asian Paints Beautiful Homes, Brooke Bond Taj Mahal, Cadbury Dairy Milk Silk, Godrej Properties, Indriya (Aditya Birla Jewellery), Lakme, Rustomjee, Titan Raga | H2: Amazon India, Bajaj Pulsar, Cadbury 5 Star, Cadbury Celebrations, Cadbury Dairy Milk, CEAT Tyres, Charged by Thums Up, Coca-Cola India, Coke Zero, DP World, Eveready Ultima, Fevicol and Fevikwik, Google India, Jio-bp, JSW Steel, Mother Dairy, PhonePe Mutual Funds, POND'S, Powerade, Revital H, Santoor, Sunfeast YiPPee!, Tata Motors Commercial Vehicles, Tata Play, Titan Eye+, Vi (Vodafone Idea) | I2: Vistara | J2: Ogilvy (Beauty & Luxury, Ogilvy West), Ogilvy India (Bengaluru), Ogilvy India (Ogilvy Delhi), Ogilvy India (Ogilvy East), Ogilvy India (Ogilvy South), Ogilvy South
A3: VML India | B3: WPP | C3: Network creative | D3: =COUNTIF('All relationships'!$A$2:$A$1227,A3) -> 21 | E3: =COUNTIFS('All relationships'!$A$2:$A$1227,A3,'All relationships'!$H$2:$H$1227,"Luxury",'All relationships'!$K$2:$K$1227,"<>Recently lost") -> 2 | F3: =COUNTIFS('All relationships'!$A$2:$A$1227,A3,'All relationships'!$H$2:$H$1227,"Premium",'All relationships'!$K$2:$K$1227,"<>Recently lost") -> 7 | G3: Anita Dongre (House of Anita Dongre) (L), MINI India (L), CenturyPly, CERA Sanitaryware, Cult.Sport, Kalapuri, Saint-Gobain India (Glass), Skoda Auto India, vivo India | H3: Apollo Tyres, Boost, Coca-Cola India, Durex, Kingfisher, KitKat, Sprite, Star Cement, Sugar Free, Thums Up, Tirupati Edible Oils | I3: Limca | J3: Studio X (VML), VML India (ex Wunderman Thompson), VMLY&R India (now VML), Wunderman Thompson India (now VML), Wunderman Thompson South Asia (now VML)
A4: Grey 82.5 (Ogilvy) | B4: WPP | C4: Network creative | D4: =COUNTIF('All relationships'!$A$2:$A$1227,A4) -> 18 | E4: =COUNTIFS('All relationships'!$A$2:$A$1227,A4,'All relationships'!$H$2:$H$1227,"Luxury",'All relationships'!$K$2:$K$1227,"<>Recently lost") -> 1 | F4: =COUNTIFS('All relationships'!$A$2:$A$1227,A4,'All relationships'!$H$2:$H$1227,"Premium",'All relationships'!$K$2:$K$1227,"<>Recently lost") -> 11 | G4: De Beers Forevermark (L), Bacardi India, Havells, Himalayan Natural Mineral Water, Indian Craft Brewery, JSW MG Motor India, Kajaria Ceramics, Kalapuri, MMTC-PAMP, Tanishq, Tata Coffee Grand Cold Coffee | H4: Axis Bank, Bandhan Mutual Fund, Imperial Blue, Luminous, Mother's Recipe, Vadilal | J4: 82.5 Communications, 82.5 Communications (Mumbai), 82.5 Communications (now Grey 82.5), AutumnGrey (Grey India), Grey 82.5, Grey 82.5 (ex Grey India / AutumnGrey), Grey 82.5 (formerly 82.5 Communications), Grey India (now Grey 82.5), Grey India and AutumnGrey
A5: Contract Advertising (VML) | B5: WPP | C5: Network creative | D5: =COUNTIF('All relationships'!$A$2:$A$1227,A5) -> 7 | E5: =COUNTIFS('All relationships'!$A$2:$A$1227,A5,'All relationships'!$H$2:$H$1227,"Luxury",'All relationships'!$K$2:$K$1227,"<>Recently lost") -> 1 | F5: =COUNTIFS('All relationships'!$A$2:$A$1227,A5,'All relationships'!$H$2:$H$1227,"Premium",'All relationships'!$K$2:$K$1227,"<>Recently lost") -> 4 | G5: BMW India (L), HSBC India, KISNA, L&T Realty, Shoppers Stop | H5: Haldiram's, Softovac | J5: Contract Advertising, Contract Advertising India (VML)
A6: Wavemaker (WPP Media) | B6: WPP | C6: Media | D6: =COUNTIF('All relationships'!$A$2:$A$1227,A6) -> 7 | E6: =COUNTIFS('All relationships'!$A$2:$A$1227,A6,'All relationships'!$H$2:$H$1227,"Luxury",'All relationships'!$K$2:$K$1227,"<>Recently lost") -> 0 | F6: =COUNTIFS('All relationships'!$A$2:$A$1227,A6,'All relationships'!$H$2:$H$1227,"Premium",'All relationships'!$K$2:$K$1227,"<>Recently lost") -> 4 | G6: Kotak Mahindra Bank, Pernod Ricard India, Red Bull India, Tata Consumer Products (portfolio) | H6: Wipro Consumer Care | I6: L'Oreal India, Netflix India | J6: Wavemaker, Wavemaker India (WPP Media)
A7: Burson India | B7: WPP | C7: PR | D7: =COUNTIF('All relationships'!$A$2:$A$1227,A7) -> 6 | E7: =COUNTIFS('All relationships'!$A$2:$A$1227,A7,'All relationships'!$H$2:$H$1227,"Luxury",'All relationships'!$K$2:$K$1227,"<>Recently lost") -> 2 | F7: =COUNTIFS('All relationships'!$A$2:$A$1227,A7,'All relationships'!$H$2:$H$1227,"Premium",'All relationships'!$K$2:$K$1227,"<>Recently lost") -> 3 | G7: Chalet Hotels (Athiva) (L), Ducati India (L), Birla Opus Paints, Honda Cars India, Mirae Asset Sharekhan | H7: Eastman Auto & Power | J7: Burson, Burson Group India
A8: Mirum India (VML) | B8: WPP | C8: Network digital | D8: =COUNTIF('All relationships'!$A$2:$A$1227,A8) -> 4 | E8: =COUNTIFS('All relationships'!$A$2:$A$1227,A8,'All relationships'!$H$2:$H$1227,"Luxury",'All relationships'!$K$2:$K$1227,"<>Recently lost") -> 0 | F8: =COUNTIFS('All relationships'!$A$2:$A$1227,A8,'All relationships'!$H$2:$H$1227,"Premium",'All relationships'!$K$2:$K$1227,"<>Recently lost") -> 2 | G8: Adani Realty, Manyavar | H8: AMFI (Mutual Funds Sahi Hai), ibis (Accor India) | J8: Mirum India (with WT Commerce)
A9: The Glitch (VML) | B9: WPP | C9: Network digital | D9: =COUNTIF('All relationships'!$A$2:$A$1227,A9) -> 4 | E9: =COUNTIFS('All relationships'!$A$2:$A$1227,A9,'All relationships'!$H$2:$H$1227,"Luxury",'All relationships'!$K$2:$K$1227,"<>Recently lost") -> 1 | F9: =COUNTIFS('All relationships'!$A$2:$A$1227,A9,'All relationships'!$H$2:$H$1227,"Premium",'All relationships'!$K$2:$K$1227,"<>Recently lost") -> 3 | G9: Diageo India Reserve portfolio (L), Diageo India (portfolio), Dove, Enamor | J9: The Glitch
A10: WPP Media | B10: WPP | C10: Media | D10: =COUNTIF('All relationships'!$A$2:$A$1227,A10) -> 3 | E10: =COUNTIFS('All relationships'!$A$2:$A$1227,A10,'All relationships'!$H$2:$H$1227,"Luxury",'All relationships'!$K$2:$K$1227,"<>Recently lost") -> 0 | F10: =COUNTIFS('All relationships'!$A$2:$A$1227,A10,'All relationships'!$H$2:$H$1227,"Premium",'All relationships'!$K$2:$K$1227,"<>Recently lost") -> 2 | G10: DAAWAT, Manyavar | I10: Flipkart | J10: EssenceMediacom, GroupM OOH Solutions (now WPP Media)
A11: Hogarth India | B11: WPP | C11: Network digital | D11: =COUNTIF('All relationships'!$A$2:$A$1227,A11) -> 1 | E11: =COUNTIFS('All relationships'!$A$2:$A$1227,A11,'All relationships'!$H$2:$H$1227,"Luxury",'All relationships'!$K$2:$K$1227,"<>Recently lost") -> 0 | F11: =COUNTIFS('All relationships'!$A$2:$A$1227,A11,'All relationships'!$H$2:$H$1227,"Premium",'All relationships'!$K$2:$K$1227,"<>Recently lost") -> 0 | H11: Federal Bank | J11: Hogarth India (WPP Production)
A12: Landor India | B12: WPP | C12: Network creative | D12: =COUNTIF('All relationships'!$A$2:$A$1227,A12) -> 1 | E12: =COUNTIFS('All relationships'!$A$2:$A$1227,A12,'All relationships'!$H$2:$H$1227,"Luxury",'All relationships'!$K$2:$K$1227,"<>Recently lost") -> 1 | F12: =COUNTIFS('All relationships'!$A$2:$A$1227,A12,'All relationships'!$H$2:$H$1227,"Premium",'All relationships'!$K$2:$K$1227,"<>Recently lost") -> 0 | G12: Dharana at Shillim (L)
A13: WPP (unit not named) | B13: WPP | C13: Network creative | D13: =COUNTIF('All relationships'!$A$2:$A$1227,A13) -> 1 | E13: =COUNTIFS('All relationships'!$A$2:$A$1227,A13,'All relationships'!$H$2:$H$1227,"Luxury",'All relationships'!$K$2:$K$1227,"<>Recently lost") -> 1 | F13: =COUNTIFS('All relationships'!$A$2:$A$1227,A13,'All relationships'!$H$2:$H$1227,"Premium",'All relationships'!$K$2:$K$1227,"<>Recently lost") -> 0 | G13: Jaguar Land Rover India (L) | J13: WPP
A14: Leo India | B14: Publicis | C14: Network creative | D14: =COUNTIF('All relationships'!$A$2:$A$1227,A14) -> 30 | E14: =COUNTIFS('All relationships'!$A$2:$A$1227,A14,'All relationships'!$H$2:$H$1227,"Luxury",'All relationships'!$K$2:$K$1227,"<>Recently lost") -> 0 | F14: =COUNTIFS('All relationships'!$A$2:$A$1227,A14,'All relationships'!$H$2:$H$1227,"Premium",'All relationships'!$K$2:$K$1227,"<>Recently lost") -> 13 | G14: Birla Opus Paints, California Almonds, HCL Group, HDFC Life, IKEA India, IndusInd Bank, Lee (India), Lenovo India, LinkedIn India, Puma India, Schneider Electric (home electricals), Sebamed, Visa | H14: ACKO, Amazon India, Bandhan Bank, BGMI (Krafton India), Cleartrip, Flipkart, Gatorade, JioMart, Lay's, Meta (India), PepsiCo India Foods & Beverages (digital), redBus, Spotify India, Sting Energy, Whisper, Zupee | I14: McDonald's India (West & South) | J14: Leo India (ex Leo Burnett Orchard)
A15: BBH India | B15: Publicis | C15: Network creative | D15: =COUNTIF('All relationships'!$A$2:$A$1227,A15) -> 14 | E15: =COUNTIFS('All relationships'!$A$2:$A$1227,A15,'All relationships'!$H$2:$H$1227,"Luxury",'All relationships'!$K$2:$K$1227,"<>Recently lost") -> 1 | F15: =COUNTIFS('All relationships'!$A$2:$A$1227,A15,'All relationships'!$H$2:$H$1227,"Premium",'All relationships'!$K$2:$K$1227,"<>Recently lost") -> 5 | G15: Taj Hotels (IHCL) (L), CaratLane, DP World, Oaksmith, Skoda Auto India | H15: CYBX, Garnier Men, HDFC Ergo, JAPFA, Microtek, Nestle Milkmaid, UniScholars, upGrad
A16: Saatchi & Saatchi India | B16: Publicis | C16: Network creative | D16: =COUNTIF('All relationships'!$A$2:$A$1227,A16) -> 14 | E16: =COUNTIFS('All relationships'!$A$2:$A$1227,A16,'All relationships'!$H$2:$H$1227,"Luxury",'All relationships'!$K$2:$K$1227,"<>Recently lost") -> 1 | F16: =COUNTIFS('All relationships'!$A$2:$A$1227,A16,'All relationships'!$H$2:$H$1227,"Premium",'All relationships'!$K$2:$K$1227,"<>Recently lost") -> 4 | G16: Audi India (L), Arvind Limited, Dunkin' India, FedEx India, Lauritz Knudsen | H16: Captain Steel, Flite, Floron, Grupo Bimbo (Bimbo Bakeries India), Hero MotoCorp, McDowell's (House of McDowell's Soda), Renault India (Kiger) | I16: Audi India, JioMart
A17: Publicis Digital Experience (ex Digitas) | B17: Publicis | C17: Network digital | D17: =COUNTIF('All relationships'!$A$2:$A$1227,A17) -> 9 | E17: =COUNTIFS('All relationships'!$A$2:$A$1227,A17,'All relationships'!$H$2:$H$1227,"Luxury",'All relationships'!$K$2:$K$1227,"<>Recently lost") -> 0 | F17: =COUNTIFS('All relationships'!$A$2:$A$1227,A17,'All relationships'!$H$2:$H$1227,"Premium",'All relationships'!$K$2:$K$1227,"<>Recently lost") -> 5 | G17: Corona, Duolingo, EquBot, Figaro and Bertolli olive oils, Matter | H17: boAt, Okaya, Renault India (Kiger) | I17: Duolingo | J17: Digitas India (now Publicis Digital Experience)
A18: BBH India (ex Publicis India) | B18: Publicis | C18: Network creative | D18: =COUNTIF('All relationships'!$A$2:$A$1227,A18) -> 8 | E18: =COUNTIFS('All relationships'!$A$2:$A$1227,A18,'All relationships'!$H$2:$H$1227,"Luxury",'All relationships'!$K$2:$K$1227,"<>Recently lost") -> 0 | F18: =COUNTIFS('All relationships'!$A$2:$A$1227,A18,'All relationships'!$H$2:$H$1227,"Premium",'All relationships'!$K$2:$K$1227,"<>Recently lost") -> 1 | G18: HDFC Mutual Fund | H18: Navratna, Nerolac Paints, Pramerica Life Insurance, ZEE TV, ZEE5 | I18: BIBA, Enamor | J18: Publicis India (merged into BBH India, Jan 2026)
A19: Propagate India (Publicis) | B19: Publicis | C19: Network digital | D19: =COUNTIF('All relationships'!$A$2:$A$1227,A19) -> 6 | E19: =COUNTIFS('All relationships'!$A$2:$A$1227,A19,'All relationships'!$H$2:$H$1227,"Luxury",'All relationships'!$K$2:$K$1227,"<>Recently lost") -> 0 | F19: =COUNTIFS('All relationships'!$A$2:$A$1227,A19,'All relationships'!$H$2:$H$1227,"Premium",'All relationships'!$K$2:$K$1227,"<>Recently lost") -> 1 | G19: Dunkin' India | H19: CremTreat, CYBX, Jio-bp, UPES | I19: Enamor | J19: Propagate India (ex Saatchi & Saatchi Propagate)
A20: Publicis Beehive | B20: Publicis | C20: Network creative | D20: =COUNTIF('All relationships'!$A$2:$A$1227,A20) -> 2 | E20: =COUNTIFS('All relationships'!$A$2:$A$1227,A20,'All relationships'!$H$2:$H$1227,"Luxury",'All relationships'!$K$2:$K$1227,"<>Recently lost") -> 0 | F20: =COUNTIFS('All relationships'!$A$2:$A$1227,A20,'All relationships'!$H$2:$H$1227,"Premium",'All relationships'!$K$2:$K$1227,"<>Recently lost") -> 0 | H20: Balaji Wafers, Storia
A21: Publicis Media | B21: Publicis | C21: Media | D21: =COUNTIF('All relationships'!$A$2:$A$1227,A21) -> 2 | E21: =COUNTIFS('All relationships'!$A$2:$A$1227,A21,'All relationships'!$H$2:$H$1227,"Luxury",'All relationships'!$K$2:$K$1227,"<>Recently lost") -> 0 | F21: =COUNTIFS('All relationships'!$A$2:$A$1227,A21,'All relationships'!$H$2:$H$1227,"Premium",'All relationships'!$K$2:$K$1227,"<>Recently lost") -> 1 | G21: L'Oreal India | H21: Flipkart | J21: Starcom
A22: BBH Singapore | B22: Publicis | C22: Network creative | D22: =COUNTIF('All relationships'!$A$2:$A$1227,A22) -> 1 | E22: =COUNTIFS('All relationships'!$A$2:$A$1227,A22,'All relationships'!$H$2:$H$1227,"Luxury",'All relationships'!$K$2:$K$1227,"<>Recently lost") -> 1 | F22: =COUNTIFS('All relationships'!$A$2:$A$1227,A22,'All relationships'!$H$2:$H$1227,"Premium",'All relationships'!$K$2:$K$1227,"<>Recently lost") -> 0 | G22: Marriott Bonvoy (India) (L)
A23: MSL India | B23: Publicis | C23: PR | D23: =COUNTIF('All relationships'!$A$2:$A$1227,A23) -> 1 | E23: =COUNTIFS('All relationships'!$A$2:$A$1227,A23,'All relationships'!$H$2:$H$1227,"Luxury",'All relationships'!$K$2:$K$1227,"<>Recently lost") -> 0 | F23: =COUNTIFS('All relationships'!$A$2:$A$1227,A23,'All relationships'!$H$2:$H$1227,"Premium",'All relationships'!$K$2:$K$1227,"<>Recently lost") -> 0 | H23: Quess Corp
A24: Team Spirit (Publicis) | B24: Publicis | C24: Network creative | D24: =COUNTIF('All relationships'!$A$2:$A$1227,A24) -> 1 | E24: =COUNTIFS('All relationships'!$A$2:$A$1227,A24,'All relationships'!$H$2:$H$1227,"Luxury",'All relationships'!$K$2:$K$1227,"<>Recently lost") -> 0 | F24: =COUNTIFS('All relationships'!$A$2:$A$1227,A24,'All relationships'!$H$2:$H$1227,"Premium",'All relationships'!$K$2:$K$1227,"<>Recently lost") -> 0 | H24: McDowell's (House of McDowell's Soda) | J24: Publicis Groupe India (Team Spirit)
